Workbook
Name InfrastructurePct: 'Hosted vs On Demand'!#REF!
Name InfrastructurePct: 'Pricing_Calculator (2)'!$A$24
Name InfrastructurePct: Pricing_Calculator!$A$24
Name InputPrice: 'Hosted vs On Demand'!#REF!
Name InputPrice: 'Pricing_Calculator (2)'!$A$8
Name InputPrice: Pricing_Calculator!$A$8
Name ModelList: 'AWS LLM Pricing'!$B$2:$B$14
Name MonthlyCaseVolume: 'Hosted vs On Demand'!#REF!
Name MonthlyCaseVolume: 'Pricing_Calculator (2)'!$A$14
Name MonthlyCaseVolume: Pricing_Calculator!$A$14
Name NumAgents: 'Hosted vs On Demand'!#REF!
Name NumAgents: 'Pricing_Calculator (2)'!$A$16
Name NumAgents: Pricing_Calculator!$A$16
Name OutputPrice: 'Hosted vs On Demand'!#REF!
Name OutputPrice: 'Pricing_Calculator (2)'!$A$10
Name OutputPrice: Pricing_Calculator!$A$10
Name SelectedModel: 'Hosted vs On Demand'!#REF!
Name SelectedModel: 'Pricing_Calculator (2)'!$A$4
Name SelectedModel: Pricing_Calculator!$A$4
Name SynthInputTokens: 'Hosted vs On Demand'!#REF!
Name SynthInputTokens: 'Pricing_Calculator (2)'!$A$20
Name SynthInputTokens: Pricing_Calculator!$A$20
Name SynthOutputTokens: 'Hosted vs On Demand'!#REF!
Name SynthOutputTokens: 'Pricing_Calculator (2)'!$A$22
Name SynthOutputTokens: Pricing_Calculator!$A$22

Sheet Pricing_Calculator
A1: CONTROL PANEL | C1: KEY METRICS DASHBOARD | H1: MODEL COMPARISON | M1: ANNUAL RANKING
A2: MODEL SELECTION | H2: Model | I2: Input $/1M | J2: Output $/1M | K2: Est. Monthly Cost | M2: ANNUAL COST RANKING
A3: Selected Model | C3: TOTAL MONTHLY COST | D3: COST PER CASE | E3: ANNUAL PROJECTION | F3: TOKENS PER CASE | H3: Claude Haiku 4.5 | I3: ='AWS LLM Pricing'!D2 -> 1 | J3: ='AWS LLM Pricing'!E2 -> 5 | K3: =((SUM(Per_Agent_Tokens!C:C)+SynthInputTokens)*I3/1000000+(SUM(Per_Agent_Tokens!D:D)+SynthOutputTokens)*J3/1000000)*MonthlyCaseVolume*(1+InfrastructurePct) -> 1557.7185 | M3: Model | N3: Annual Cost
A4: Claude Sonnet 4.6 | C4: =((SUM(Per_Agent_Tokens!C:C)+SynthInputTokens)*InputPrice/1000000+(SUM(Per_Agent_Tokens!D:D)+SynthOutputTokens)*OutputPrice/1000000)*MonthlyCaseVolume*(1+InfrastructurePct) -> 4673.1555 | D4: =C4/MonthlyCaseVolume -> 0.9346311 | E4: =C4*12 -> 56077.866 | F4: =SUM(Per_Agent_Tokens!C:C)+SUM(Per_Agent_Tokens!D:D)+SynthInputTokens+SynthOutputTokens -> 149149 | H4: Claude Sonnet 4.6 | I4: ='AWS LLM Pricing'!D3 -> 3 | J4: ='AWS LLM Pricing'!E3 -> 15 | K4: =((SUM(Per_Agent_Tokens!C:C)+SynthInputTokens)*I4/1000000+(SUM(Per_Agent_Tokens!D:D)+SynthOutputTokens)*J4/1000000)*MonthlyCaseVolume*(1+InfrastructurePct) -> 4673.1555 | M4: {=_xlfn._xlws.SORT(_xlfn.HSTACK(C44:C51,O44:O51),2,-1)} -> Claude Opus 4.7 | N4: 93463.11
H5: Claude Opus 4.7 | I5: ='AWS LLM Pricing'!D4 -> 5 | J5: ='AWS LLM Pricing'!E4 -> 25 | K5: =((SUM(Per_Agent_Tokens!C:C)+SynthInputTokens)*I5/1000000+(SUM(Per_Agent_Tokens!D:D)+SynthOutputTokens)*J5/1000000)*MonthlyCaseVolume*(1+InfrastructurePct) -> 7788.5925 | M5: Claude Sonnet 4.6 | N5: 56077.866
A6: TOKEN PRICING | C6: INPUT TOKENS/CASE | D6: OUTPUT TOKENS/CASE | E6: INPUT:OUTPUT RATIO | F6: DAILY COST | H6: Nova Micro | I6: ='AWS LLM Pricing'!D5 -> 0.035 | J6: ='AWS LLM Pricing'!E5 -> 0.14 | K6: =((SUM(Per_Agent_Tokens!C:C)+SynthInputTokens)*I6/1000000+(SUM(Per_Agent_Tokens!D:D)+SynthOutputTokens)*J6/1000000)*MonthlyCaseVolume*(1+InfrastructurePct) -> 49.37296 | M6: Nova Premier | N6: 46731.555
A7: Input (per 1M tokens) | C7: =SUM(Per_Agent_Tokens!C:C)+SynthInputTokens -> 126524 | D7: =SUM(Per_Agent_Tokens!D:D)+SynthOutputTokens -> 22625 | E7: =ROUND(C7/D7,1)&" : 1" -> 5.6 : 1 | F7: =C4/30 -> 155.77185 | H7: Nova Lite | I7: ='AWS LLM Pricing'!D6 -> 0.06 | J7: ='AWS LLM Pricing'!E6 -> 0.24 | K7: =((SUM(Per_Agent_Tokens!C:C)+SynthInputTokens)*I7/1000000+(SUM(Per_Agent_Tokens!D:D)+SynthOutputTokens)*J7/1000000)*MonthlyCaseVolume*(1+InfrastructurePct) -> 84.63936 | M7: Claude Haiku 4.5 | N7: 18692.622
A8: =VLOOKUP(A4,'AWS LLM Pricing'!B:E,3,FALSE) -> 3 | H8: Nova Pro | I8: ='AWS LLM Pricing'!D7 -> 0.8 | J8: ='AWS LLM Pricing'!E7 -> 3.2 | K8: =((SUM(Per_Agent_Tokens!C:C)+SynthInputTokens)*I8/1000000+(SUM(Per_Agent_Tokens!D:D)+SynthOutputTokens)*J8/1000000)*MonthlyCaseVolume*(1+InfrastructurePct) -> 1128.5248 | M8: Nova Pro | N8: 13542.298
A9: Output (per 1M tokens) | C9: COST BREAKDOWN (Per 1M Tokens) | H9: Nova Premier | I9: ='AWS LLM Pricing'!D8 -> 2.5 | J9: ='AWS LLM Pricing'!E8 -> 12.5 | K9: =((SUM(Per_Agent_Tokens!C:C)+SynthInputTokens)*I9/1000000+(SUM(Per_Agent_Tokens!D:D)+SynthOutputTokens)*J9/1000000)*MonthlyCaseVolume*(1+InfrastructurePct) -> 3894.2963 | M9: Llama 3.3 70B | N9: 8376.2078
A10: =VLOOKUP(A4,'AWS LLM Pricing'!B:E,4,FALSE) -> 15 | C10: Component | D10: Monthly Cost | E10: % of Total | H10: Llama 3.3 70B | I10: ='AWS LLM Pricing'!D9 -> 0.72 | J10: ='AWS LLM Pricing'!E9 -> 0.72 | K10: =((SUM(Per_Agent_Tokens!C:C)+SynthInputTokens)*I10/1000000+(SUM(Per_Agent_Tokens!D:D)+SynthOutputTokens)*J10/1000000)*MonthlyCaseVolume*(1+InfrastructurePct) -> 698.01732 | M10: Nova Lite | N10: 1015.6723
C11: Input Tokens | D11: =(SUM(Per_Agent_Tokens!C:C)+SynthInputTokens)*InputPrice/1000000*MonthlyCaseVolume -> 1897.86 | E11: =D11/$D$14 -> 0.40611959 | M11: Nova Micro | N11: 592.47552
A12: VOLUME SETTINGS | C12: Output Tokens | D12: =(SUM(Per_Agent_Tokens!D:D)+SynthOutputTokens)*OutputPrice/1000000*MonthlyCaseVolume -> 1696.875 | E12: =D12/$D$14 -> 0.36311118 | H12: CATEGORY TOKEN USAGE
A13: Monthly Case Volume | C13: Infrastructure | D13: =(D11+D12)*InfrastructurePct -> 1078.4205 | E13: =D13/$D$14 -> 0.23076923 | H13: Category | I13: Agents | J13: Total Tokens | K13: % of Total
A14: 5000 | C14: TOTAL | D14: =SUM(D11:D13) -> 4673.1555 | E14: =SUM(E11:E13) -> 1 | H14: Income | I14: =Category_Breakdown!B2 -> 7 | J14: =Category_Breakdown!E2 -> 23444 | K14: =J14/SUM(Category_Breakdown!E2:E10) -> 0.17093818
A15: Number of Agents | H15: Non-Financial | I15: =Category_Breakdown!B3 -> 5 | J15: =Category_Breakdown!E3 -> 22087 | K15: =J15/SUM(Category_Breakdown!E2:E10) -> 0.16104383
A16: 38 | C16: OPTIMIZATION SCENARIOS | H16: Residency/Citizenship | I16: =Category_Breakdown!B4 -> 5 | J16: =Category_Breakdown!E4 -> 19919 | K16: =J16/SUM(Category_Breakdown!E2:E10) -> 0.1452362
C17: Scenario | D17: Est. Tokens | E17: Reduction | F17: Monthly Savings | H17: Verification/Docs | I17: =Category_Breakdown!B5 -> 5 | J17: =Category_Breakdown!E5 -> 18567 | K17: =J17/SUM(Category_Breakdown!E2:E10) -> 0.13537831
A18: OVERHEAD CONFIG | C18: Full Naive Run | D18: =Z_Optimization_Scenarios!C2 -> 137149 | E18: =Z_Optimization_Scenarios!D2/100 -> 0 | F18: 0 | H18: Identity/Household | I18: =Category_Breakdown!B6 -> 4 | J18: =Category_Breakdown!E6 -> 16233 | K18: =J18/SUM(Category_Breakdown!E2:E10) -> 0.11836032
A19: Synthesis Input Tokens | C19: Core Only Run | D19: =Z_Optimization_Scenarios!C3 -> 112114 | E19: =Z_Optimization_Scenarios!D3/100 -> 0.183 | F19: =C4*(1-D19/Z_Optimization_Scenarios!C2) -> 853.03172 | H19: Resources | I19: =Category_Breakdown!B7 -> 5 | J19: =Category_Breakdown!E7 -> 15564 | K19: =J19/SUM(Category_Breakdown!E2:E10) -> 0.11348242
A20: 10000 | C20: Context Sharing | D20: =Z_Optimization_Scenarios!C4 -> 95000 | E20: =Z_Optimization_Scenarios!D4/100 -> 0.307 | F20: =C4*(1-D20/Z_Optimization_Scenarios!C2) -> 1436.1667 | H20: Categorical Det. | I20: =Category_Breakdown!B8 -> 3 | J20: =Category_Breakdown!E8 -> 9215 | K20: =J20/SUM(Category_Breakdown!E2:E10) -> 0.067189699
A21: Synthesis Output Tokens | C21: Hierarchical Design | D21: =Z_Optimization_Scenarios!C5 -> 85000 | E21: =Z_Optimization_Scenarios!D5/100 -> 0.38 | F21: =C4*(1-D21/Z_Optimization_Scenarios!C2) -> 1776.9024 | H21: Deductions | I21: =Category_Breakdown!B9 -> 2 | J21: =Category_Breakdown!E9 -> 6434 | K21: =J21/SUM(Category_Breakdown!E2:E10) -> 0.046912482
A22: 2000 | C22: Hybrid Rules+LLM | D22: =Z_Optimization_Scenarios!C6 -> 65000 | E22: =Z_Optimization_Scenarios!D6/100 -> 0.526 | F22: =C4*(1-D22/Z_Optimization_Scenarios!C2) -> 2458.3737 | H22: Timeliness | I22: =Category_Breakdown!B10 -> 2 | J22: =Category_Breakdown!E10 -> 5686 | K22: =J22/SUM(Category_Breakdown!E2:E10) -> 0.04145856
A23: Infrastructure Cost %
A24: 0.3
C41: MULTI-MODEL COST ANALYSIS
C42: ANNUAL COST PROJECTION BY MODEL
C43: Model | D43: Jan | E43: Feb | F43: Mar | G43: Apr | H43: May | I43: Jun | J43: Jul | K43: Aug | L43: Sep | M43: Oct | N43: Nov | O43: Dec
C44: =H3 -> Claude Haiku 4.5 | D44: =K3*1 -> 1557.7185 | E44: =K3*2 -> 3115.437 | F44: =K3*3 -> 4673.1555 | G44: =K3*4 -> 6230.874 | H44: =K3*5 -> 7788.5925 | I44: =K3*6 -> 9346.311 | J44: =K3*7 -> 10904.03 | K44: =K3*8 -> 12461.748 | L44: =K3*9 -> 14019.466 | M44: =K3*10 -> 15577.185 | N44: =K3*11 -> 17134.904 | O44: =K3*12 -> 18692.622
C45: =H4 -> Claude Sonnet 4.6 | D45: =K4*1 -> 4673.1555 | E45: =K4*2 -> 9346.311 | F45: =K4*3 -> 14019.467 | G45: =K4*4 -> 18692.622 | H45: =K4*5 -> 23365.778 | I45: =K4*6 -> 28038.933 | J45: =K4*7 -> 32712.089 | K45: =K4*8 -> 37385.244 | L45: =K4*9 -> 42058.4 | M45: =K4*10 -> 46731.555 | N45: =K4*11 -> 51404.711 | O45: =K4*12 -> 56077.866
C46: =H5 -> Claude Opus 4.7 | D46: =K5*1 -> 7788.5925 | E46: =K5*2 -> 15577.185 | F46: =K5*3 -> 23365.778 | G46: =K5*4 -> 31154.37 | H46: =K5*5 -> 38942.963 | I46: =K5*6 -> 46731.555 | J46: =K5*7 -> 54520.148 | K46: =K5*8 -> 62308.74 | L46: =K5*9 -> 70097.333 | M46: =K5*10 -> 77885.925 | N46: =K5*11 -> 85674.518 | O46: =K5*12 -> 93463.11
C47: =H6 -> Nova Micro | D47: =K6*1 -> 49.37296 | E47: =K6*2 -> 98.74592 | F47: =K6*3 -> 148.11888 | G47: =K6*4 -> 197.49184 | H47: =K6*5 -> 246.8648 | I47: =K6*6 -> 296.23776 | J47: =K6*7 -> 345.61072 | K47: =K6*8 -> 394.98368 | L47: =K6*9 -> 444.35664 | M47: =K6*10 -> 493.7296 | N47: =K6*11 -> 543.10256 | O47: =K6*12 -> 592.47552
C48: =H7 -> Nova Lite | D48: =K7*1 -> 84.63936 | E48: =K7*2 -> 169.27872 | F48: =K7*3 -> 253.91808 | G48: =K7*4 -> 338.55744 | H48: =K7*5 -> 423.1968 | I48: =K7*6 -> 507.83616 | J48: =K7*7 -> 592.47552 | K48: =K7*8 -> 677.11488 | L48: =K7*9 -> 761.75424 | M48: =K7*10 -> 846.3936 | N48: =K7*11 -> 931.03296 | O48: =K7*12 -> 1015.6723
C49: =H8 -> Nova Pro | D49: =K8*1 -> 1128.5248 | E49: =K8*2 -> 2257.0496 | F49: =K8*3 -> 3385.5744 | G49: =K8*4 -> 4514.0992 | H49: =K8*5 -> 5642.624 | I49: =K8*6 -> 6771.1488 | J49: =K8*7 -> 7899.6736 | K49: =K8*8 -> 9028.1984 | L49: =K8*9 -> 10156.723 | M49: =K8*10 -> 11285.248 | N49: =K8*11 -> 12413.773 | O49: =K8*12 -> 13542.298
C50: =H9 -> Nova Premier | D50: =K9*1 -> 3894.2963 | E50: =K9*2 -> 7788.5925 | F50: =K9*3 -> 11682.889 | G50: =K9*4 -> 15577.185 | H50: =K9*5 -> 19471.481 | I50: =K9*6 -> 23365.778 | J50: =K9*7 -> 27260.074 | K50: =K9*8 -> 31154.37 | L50: =K9*9 -> 35048.666 | M50: =K9*10 -> 38942.963 | N50: =K9*11 -> 42837.259 | O50: =K9*12 -> 46731.555
C51: =H10 -> Llama 3.3 70B | D51: =K10*1 -> 698.01732 | E51: =K10*2 -> 1396.0346 | F51: =K10*3 -> 2094.052 | G51: =K10*4 -> 2792.0693 | H51: =K10*5 -> 3490.0866 | I51: =K10*6 -> 4188.1039 | J51: =K10*7 -> 4886.1212 | K51: =K10*8 -> 5584.1386 | L51: =K10*9 -> 6282.1559 | M51: =K10*10 -> 6980.1732 | N51: =K10*11 -> 7678.1905 | O51: =K10*12 -> 8376.2078

Sheet Hosted vs On Demand
B1: MODEL COMPARISON CONTROLS
B2: Select models below to dynamically compare Hosted vs On-Demand costs
B3: SELECT HOSTED MODEL | E3: SELECT ON-DEMAND MODEL | H3: LIVE COMPARISON RESULTS
B4: Llama | E4: Nova Micro | H4: Hosted Monthly | I4: (Annual) | J4: On-Demand Monthly | K4: (Annual) | L4: Monthly Savings | M4: Savings % | N4: Winner
H5: =VLOOKUP(B4,B15:G20,6,FALSE) -> 2472.126 | I5: =H5*12 -> 29665.512 | J5: =VLOOKUP(E4,I15:M22,5,FALSE) -> 114.66788 | K5: =J5*12 -> 1376.0145 | L5: =H5-J5 -> 2357.4581 | M5: =IF(H5>0,(H5-J5)/H5,0) -> 0.95361568 | N5: =IF(H5>J5,"ON-DEMAND","HOSTED") -> ON-DEMAND
B6: HOSTED vs ON-DEMAND COST ANALYSIS | P6: Model | Q6: Monthly Cost | T6: Model | U6: Cost
B7: Self-Hosted Infrastructure vs Pay-Per-Use Models | P7: Nova Premier | Q7: =C44 -> 9772.1125 | R7: Type | T7: Nova Premier | U7: =M18 -> 9772.1125
P8: Hosted OpenAI | Q8: =C42 -> 2472.126 | R8: Hosted | T8: Hosted OpenAI | U8: =G20 -> 6192.51
B9: KEY PARAMETERS | P9: Claude Haiku 4.5 | Q9: =C45 -> 3908.845 | R9: Hosted | T9: Claude Haiku 4.5 | U9: =M20 -> 3908.845
B10: Monthly Case Volume | C10: Tokens Per Case | D10: Input Tokens | E10: Output Tokens | P10: Nova Pro | Q10: =C46 -> 2620.98 | R10: On-Demand | T10: Nova Pro | U10: =M17 -> 2620.98
B11: =Pricing_Calculator!A14 -> 5000 | C11: =Pricing_Calculator!F4 -> 149149 | D11: =Pricing_Calculator!C7 -> 126524 | E11: =Pricing_Calculator!D7 -> 22625 | P11: Hosted Llama | Q11: =C43 -> 114.66788 | R11: On-Demand | T11: Hosted Llama | U11: =G15 -> 2472.126
P12: Llama 3.3 70B | Q12: =C47 -> 992.4228 | R12: On-Demand | T12: Llama 3.3 70B | U12: =M19 -> 992.4228
B13: SELF-HOSTED INFRASTRUCTURE COSTS | I13: ON-DEMAND PAY-PER-USE COSTS | P13: Nova Lite | Q13: =C48 -> 196.5735 | R13: On-Demand | T13: Nova Lite | U13: =M16 -> 196.5735
B14: Model | C14: Cost/Min | D14: Storage/Unit | E14: Hourly Cost | F14: Daily Cost | G14: Monthly Cost | I14: Model | J14: Input $/1M | K14: Output $/1M | L14: Cost/Case | M14: Monthly Cost | N14: Annual Cost | P14: Nova Micro | Q14: =C49 -> 114.66788 | R14: On-Demand | T14: Nova Micro | U14: =M15 -> 114.66788
B15: Llama | C15: ='AWS LLM Pricing'!B22 -> 0.05718 | D15: ='AWS LLM Pricing'!C22 -> 1.95 | E15: =C15*60 -> 3.4308 | F15: =E15*24 -> 82.3392 | G15: =F15*30+D15 -> 2472.126 | I15: Nova Micro | J15: ='AWS LLM Pricing'!D5 -> 0.035 | K15: ='AWS LLM Pricing'!E5 -> 0.14 | L15: =($C$11*J15+$D$11*K15)/1000000 -> 0.022933575 | M15: =L15*$B$11 -> 114.66788 | N15: =M15*12 -> 1376.0145
B16: Mistral | C16: ='AWS LLM Pricing'!B23 -> 0.05718 | D16: ='AWS LLM Pricing'!C23 -> 1.95 | E16: =C16*60 -> 3.4308 | F16: =E16*24 -> 82.3392 | G16: =F16*30+D16 -> 2472.126 | I16: Nova Lite | J16: ='AWS LLM Pricing'!D6 -> 0.06 | K16: ='AWS LLM Pricing'!E6 -> 0.24 | L16: =($C$11*J16+$D$11*K16)/1000000 -> 0.0393147 | M16: =L16*$B$11 -> 196.5735 | N16: =M16*12 -> 2358.882
B17: Mixtral | C17: ='AWS LLM Pricing'!B24 -> 0.05718 | D17: ='AWS LLM Pricing'!C24 -> 1.95 | E17: =C17*60 -> 3.4308 | F17: =E17*24 -> 82.3392 | G17: =F17*30+D17 -> 2472.126 | I17: Nova Pro | J17: ='AWS LLM Pricing'!D7 -> 0.8 | K17: ='AWS LLM Pricing'!E7 -> 3.2 | L17: =($C$11*J17+$D$11*K17)/1000000 -> 0.524196 | M17: =L17*$B$11 -> 2620.98 | N17: =M17*12 -> 31451.76 | R17: On-Demand (Nova Micro) | S17: Break-Even Line
B18: Flan | C18: ='AWS LLM Pricing'!B25 -> 0.05718 | D18: ='AWS LLM Pricing'!C25 -> 1.95 | E18: =C18*60 -> 3.4308 | F18: =E18*24 -> 82.3392 | G18: =F18*30+D18 -> 2472.126 | I18: Nova Premier | J18: ='AWS LLM Pricing'!D8 -> 2.5 | K18: ='AWS LLM Pricing'!E8 -> 12.5 | L18: =($C$11*J18+$D$11*K18)/1000000 -> 1.9544225 | M18: =L18*$B$11 -> 9772.1125 | N18: =M18*12 -> 117265.35 | P18: =I26 -> 1000 | Q18: =J26 -> 2472.126 | R18: =K26 -> 22.933575 | S18: =$G$15 -> 2472.126
B19: Qwen | C19: ='AWS LLM Pricing'!B26 -> 0.05718 | D19: ='AWS LLM Pricing'!C26 -> 1.95 | E19: =C19*60 -> 3.4308 | F19: =E19*24 -> 82.3392 | G19: =F19*30+D19 -> 2472.126 | I19: Llama 3.3 70B | J19: ='AWS LLM Pricing'!D9 -> 0.72 | K19: ='AWS LLM Pricing'!E9 -> 0.72 | L19: =($C$11*J19+$D$11*K19)/1000000 -> 0.19848456 | M19: =L19*$B$11 -> 992.4228 | N19: =M19*12 -> 11909.074 | P19: =I27 -> 3000 | Q19: =J27 -> 2472.126 | R19: =K27 -> 68.800725 | S19: =$G$15 -> 2472.126
B20: OpenAI | C20: ='AWS LLM Pricing'!B27 -> 0.1433 | D20: ='AWS LLM Pricing'!C27 -> 1.95 | E20: =C20*60 -> 8.598 | F20: =E20*24 -> 206.352 | G20: =F20*30+D20 -> 6192.51 | I20: Claude Haiku 4.5 | J20: ='AWS LLM Pricing'!D2 -> 1 | K20: ='AWS LLM Pricing'!E2 -> 5 | L20: =($C$11*J20+$D$11*K20)/1000000 -> 0.781769 | M20: =L20*$B$11 -> 3908.845 | N20: =M20*12 -> 46906.14 | P20: =I28 -> 6000 | Q20: =J28 -> 2472.126 | R20: =K28 -> 137.60145 | S20: =$G$15 -> 2472.126
I21: Claude Sonnet 4.6 | J21: ='AWS LLM Pricing'!D3 -> 3 | K21: ='AWS LLM Pricing'!E3 -> 15 | L21: =($C$11*J21+$D$11*K21)/1000000 -> 2.345307 | M21: =L21*$B$11 -> 11726.535 | N21: =M21*12 -> 140718.42 | P21: =I29 -> 10000 | Q21: =J29 -> 2472.126 | R21: =K29 -> 229.33575 | S21: =$G$15 -> 2472.126
I22: Claude Opus 4.7 | J22: ='AWS LLM Pricing'!D4 -> 5 | K22: ='AWS LLM Pricing'!E4 -> 25 | L22: =($C$11*J22+$D$11*K22)/1000000 -> 3.908845 | M22: =L22*$B$11 -> 19544.225 | N22: =M22*12 -> 234530.7 | P22: =I30 -> 25000 | Q22: =J30 -> 2472.126 | R22: =K30 -> 573.33938 | S22: =$G$15 -> 2472.126
P23: =I31 -> 50000 | Q23: =J31 -> 2472.126 | R23: =K31 -> 1146.6788 | S23: =$G$15 -> 2472.126
B24: EXECUTIVE SUMMARY | I24: VOLUME SENSITIVITY ANALYSIS | P24: =I32 -> 100000 | Q24: =J32 -> 2472.126 | R24: =K32 -> 2293.3575 | S24: =$G$15 -> 2472.126
B25: Metric | C25: ="Hosted ("&B4&")" -> Hosted (Llama) | D25: ="On-Demand ("&E4&")" -> On-Demand (Nova Micro) | E25: Savings | F25: Savings % | G25: Recommendation | I25: Monthly Cases | J25: ="Hosted "&B4 -> Hosted Llama | K25: ="On-Demand "&E4 -> On-Demand Nova Micro | L25: Difference | M25: Better Option | N25: Savings % | P25: =I33 -> 200000 | Q25: =J33 -> 2472.126 | R25: =K33 -> 4586.715 | S25: =$G$15 -> 2472.126
B26: Monthly Cost | C26: =H5 -> 2472.126 | D26: =J5 -> 114.66788 | E26: =C26-D26 -> 2357.4581 | F26: =IF(C26>0,E26/C26,0) -> 0.95361568 | G26: =IF(C26>D26,"ON-DEMAND","HOSTED") -> ON-DEMAND | I26: 1000 | J26: =VLOOKUP(B4,B15:G20,6,FALSE) -> 2472.126 | K26: =VLOOKUP(E4,I15:M22,4,FALSE)*I26 -> 22.933575 | L26: =J26-K26 -> 2449.1924 | M26: =IF(K26<J26,"On-Demand","Hosted") -> On-Demand | N26: =IF(J26>0,MAX(0,(J26-K26)/J26),0) -> 0.99072314 | P26: =I34 -> 500000 | Q26: =J34 -> 2472.126 | R26: =K34 -> 11466.788 | S26: =$G$15 -> 2472.126
B27: Annual Cost | C27: =I5 -> 29665.512 | D27: =K5 -> 1376.0145 | E27: =C27-D27 -> 28289.498 | F27: =IF(C27>0,E27/C27,0) -> 0.95361568 | G27: =IF(C27>D27,"ON-DEMAND","HOSTED") -> ON-DEMAND | I27: 3000 | J27: =VLOOKUP(B4,B15:G20,6,FALSE) -> 2472.126 | K27: =VLOOKUP(E4,I15:M22,4,FALSE)*I27 -> 68.800725 | L27: =J27-K27 -> 2403.3253 | M27: =IF(K27<J27,"On-Demand","Hosted") -> On-Demand | N27: =IF(J27>0,MAX(0,(J27-K27)/J27),0) -> 0.97216941 | P27: =I35 -> 1000000 | Q27: =J35 -> 2472.126 | R27: =K35 -> 22933.575 | S27: =$G$15 -> 2472.126
B28: Cost Per Case | C28: =H5/B11 -> 0.4944252 | D28: =VLOOKUP(E4,I15:M22,4,FALSE) -> 0.022933575 | E28: =C28-D28 -> 0.47149163 | F28: =IF(C28>0,E28/C28,0) -> 0.95361568 | G28: =IF(C28>D28,"ON-DEMAND","HOSTED") -> ON-DEMAND | I28: 6000 | J28: =VLOOKUP(B4,B15:G20,6,FALSE) -> 2472.126 | K28: =VLOOKUP(E4,I15:M22,4,FALSE)*I28 -> 137.60145 | L28: =J28-K28 -> 2334.5246 | M28: =IF(K28<J28,"On-Demand","Hosted") -> On-Demand | N28: =IF(J28>0,MAX(0,(J28-K28)/J28),0) -> 0.94433882
B29: Break-Even Volume | C29: =IF(D28>0,ROUND(H5/D28,0),"N/A") -> 107795 | D29: N/A | E29: =C29-B11 -> 102795 | F29: =IF(C29>0,(C29-B11)/C29,0) -> 0.95361566 | G29: =IF(B11<C29,"Below break-even","Above break-even") -> Below break-even | I29: 10000 | J29: =VLOOKUP(B4,B15:G20,6,FALSE) -> 2472.126 | K29: =VLOOKUP(E4,I15:M22,4,FALSE)*I29 -> 229.33575 | L29: =J29-K29 -> 2242.7903 | M29: =IF(K29<J29,"On-Demand","Hosted") -> On-Demand | N29: =IF(J29>0,MAX(0,(J29-K29)/J29),0) -> 0.90723137 | P29: Annual Cost Ranking
B30: Utilization Rate | C30: =IF(C29>0,B11/C29,0) -> 0.046384341 | D30: 1 | G30: =IF(C30<0.5,"Low utilization","High utilization") -> Low utilization | I30: 25000 | J30: =VLOOKUP(B4,B15:G20,6,FALSE) -> 2472.126 | K30: =VLOOKUP(E4,I15:M22,4,FALSE)*I30 -> 573.33938 | L30: =J30-K30 -> 1898.7866 | M30: =IF(K30<J30,"On-Demand","Hosted") -> On-Demand | N30: =IF(J30>0,MAX(0,(J30-K30)/J30),0) -> 0.76807842 | P30: Model | Q30: Annual Cost | R30: Type
I31: 50000 | J31: =VLOOKUP(B4,B15:G20,6,FALSE) -> 2472.126 | K31: =VLOOKUP(E4,I15:M22,4,FALSE)*I31 -> 1146.6788 | L31: =J31-K31 -> 1325.4473 | M31: =IF(K31<J31,"On-Demand","Hosted") -> On-Demand | N31: =IF(J31>0,MAX(0,(J31-K31)/J31),0) -> 0.53615683 | P31: Hosted OpenAI | Q31: =G20*12 -> 74310.12 | R31: Hosted
B32: STRATEGIC RECOMMENDATION | I32: 100000 | J32: =VLOOKUP(B4,B15:G20,6,FALSE) -> 2472.126 | K32: =VLOOKUP(E4,I15:M22,4,FALSE)*I32 -> 2293.3575 | L32: =J32-K32 -> 178.7685 | M32: =IF(K32<J32,"On-Demand","Hosted") -> On-Demand | N32: =IF(J32>0,MAX(0,(J32-K32)/J32),0) -> 0.072313668 | P32: Hosted Llama | Q32: =G15*12 -> 29665.512 | R32: Hosted
B33: ="RECOMMENDATION: USE "&N5&" MODELS" -> RECOMMENDATION: USE ON-DEMAND MODELS | I33: 200000 | J33: =VLOOKUP(B4,B15:G20,6,FALSE) -> 2472.126 | K33: =VLOOKUP(E4,I15:M22,4,FALSE)*I33 -> 4586.715 | L33: =J33-K33 -> -2114.589 | M33: =IF(K33<J33,"On-Demand","Hosted") -> Hosted | N33: =IF(J33>0,MAX(0,(J33-K33)/J33),0) -> 0 | P33: Claude Opus 4.7 | Q33: =N22 -> 234530.7 | R33: On-Demand
I34: 500000 | J34: =VLOOKUP(B4,B15:G20,6,FALSE) -> 2472.126 | K34: =VLOOKUP(E4,I15:M22,4,FALSE)*I34 -> 11466.788 | L34: =J34-K34 -> -8994.6615 | M34: =IF(K34<J34,"On-Demand","Hosted") -> Hosted | N34: =IF(J34>0,MAX(0,(J34-K34)/J34),0) -> 0 | P34: Claude Sonnet 4.6 | Q34: =N21 -> 140718.42 | R34: On-Demand
B35: Current Volume: | C35: =B11 -> 5000 | D35: cases/month | E35: =IF(VLOOKUP(E4,I15:M22,4,FALSE)>0,H5/VLOOKUP(E4,I15:M22,4,FALSE),0) -> 107795.06 | F35: =C29 -> 107795 | G35: cases/month | I35: 1000000 | J35: =VLOOKUP(B4,B15:G20,6,FALSE) -> 2472.126 | K35: =VLOOKUP(E4,I15:M22,4,FALSE)*I35 -> 22933.575 | L35: =J35-K35 -> -20461.449 | M35: =IF(K35<J35,"On-Demand","Hosted") -> Hosted | N35: =IF(J35>0,MAX(0,(J35-K35)/J35),0) -> 0 | P35: Claude Haiku 4.5 | Q35: =N20 -> 46906.14 | R35: On-Demand
B36: Monthly Savings: | C36: =L5 -> 2357.4581 | E36: Annual Savings: | F36: =L5*12 -> 28289.498 | P36: Nova Premier | Q36: =N18 -> 117265.35 | R36: On-Demand
B37: Savings Rate: | C37: =M5 -> 0.95361568 | E37: Volume Headroom: | F37: =MAX(0,C29-B11) -> 102795 | G37: cases | P37: Nova Pro | Q37: =N17 -> 31451.76 | R37: On-Demand
B38: Best On-Demand: | C38: =E4 -> Nova Micro | E38: Best Hosted: | F38: =B4 -> Llama | I38: Volume | J38: ="Hosted ("&B4&")" -> Hosted (Llama) | K38: ="On-Demand ("&E4&")" -> On-Demand (Nova Micro) | L38: Break-Even | P38: Llama 3.3 70B | Q38: =N19 -> 11909.074 | R38: On-Demand
I39: 1000 | J39: =VLOOKUP(B4,B15:G20,6,FALSE) -> 2472.126 | K39: =VLOOKUP(E4,I15:M22,4,FALSE)*I39 -> 22.933575 | L39: =IF(I39<$C$29,$H$5,NA()) -> 2472.126 | P39: Nova Lite | Q39: =N16 -> 2358.882 | R39: On-Demand
B40: ="COST SCALING BY VOLUME" -> COST SCALING BY VOLUME | P40: Nova Micro | Q40: =N15 -> 1376.0145 | R40: On-Demand
...

Sheet Pricing_Calculator (2)
A1: CONTROL PANEL | C1: KEY METRICS DASHBOARD | H1: MODEL COMPARISON | M1: ANNUAL RANKING | AB1: CHART DATA (Helper) | AE1: VOLUME CHART DATA
A2: MODEL SELECTION | H2: Model | I2: Input $/1M | J2: Output $/1M | K2: Est. Monthly Cost | M2: ANNUAL COST RANKING | AB2: Model | AC2: Monthly Cost | AE2: Volume | AF2: Hosted Llama | AG2: Hosted OpenAI | AH2: Nova Micro | AI2: Nova Pro | AJ2: Llama 3.3
A3: Selected Model | C3: TOTAL MONTHLY COST | D3: COST PER CASE | E3: ANNUAL PROJECTION | F3: TOKENS PER CASE | H3: Claude Haiku 4.5 | I3: ='AWS LLM Pricing'!D2 -> 1 | J3: ='AWS LLM Pricing'!E2 -> 5 | K3: =((SUM(Per_Agent_Tokens!C:C)+SynthInputTokens)*I3/1000000+(SUM(Per_Agent_Tokens!D:D)+SynthOutputTokens)*J3/1000000)*MonthlyCaseVolume*(1+InfrastructurePct) -> 1797.4728 | M3: Model | N3: Annual Cost | AB3: Hosted OpenAI | AC3: =H92 -> 6192.51 | AE3: 1000 | AF3: =$H$87 -> 2472.126 | AG3: =$H$92 -> 6192.51 | AH3: =($I$6*$C$7/1000000+$J$6*$D$7/1000000)*AE3*(1+$A$24) -> 9.451008 | AI3: =($I$8*$C$7/1000000+$J$8*$D$7/1000000)*AE3*(1+$A$24) -> 216.02304 | AJ3: =($I$10*$C$7/1000000+$J$10*$D$7/1000000)*AE3*(1+$A$24) -> 130.59274
A4: Nova Pro | C4: =((SUM(Per_Agent_Tokens!C:C)+SynthInputTokens)*InputPrice/1000000+(SUM(Per_Agent_Tokens!D:D)+SynthOutputTokens)*OutputPrice/1000000)*MonthlyCaseVolume*(1+InfrastructurePct) -> 1296.1382 | D4: =C4/MonthlyCaseVolume -> 0.21602304 | E4: =C4*12 -> 15553.659 | F4: =SUM(Per_Agent_Tokens!C:C)+SUM(Per_Agent_Tokens!D:D)+SynthInputTokens+SynthOutputTokens -> 151149 | H4: Claude Sonnet 4.6 | I4: ='AWS LLM Pricing'!D3 -> 3 | J4: ='AWS LLM Pricing'!E3 -> 15 | K4: =((SUM(Per_Agent_Tokens!C:C)+SynthInputTokens)*I4/1000000+(SUM(Per_Agent_Tokens!D:D)+SynthOutputTokens)*J4/1000000)*MonthlyCaseVolume*(1+InfrastructurePct) -> 5392.4184 | M4: {=_xlfn._xlws.SORT(_xlfn.HSTACK(C44:C51,O44:O51),2,-1)} -> Claude Opus 4.7 | N4: 107848.37 | AB4: Hosted Llama | AC4: =H87 -> 2472.126 | AE4: 3000 | AF4: =$H$87 -> 2472.126 | AG4: =$H$92 -> 6192.51 | AH4: =($I$6*$C$7/1000000+$J$6*$D$7/1000000)*AE4*(1+$A$24) -> 28.353024 | AI4: =($I$8*$C$7/1000000+$J$8*$D$7/1000000)*AE4*(1+$A$24) -> 648.06912 | AJ4: =($I$10*$C$7/1000000+$J$10*$D$7/1000000)*AE4*(1+$A$24) -> 391.77821
H5: Claude Opus 4.7 | I5: ='AWS LLM Pricing'!D4 -> 5 | J5: ='AWS LLM Pricing'!E4 -> 25 | K5: =((SUM(Per_Agent_Tokens!C:C)+SynthInputTokens)*I5/1000000+(SUM(Per_Agent_Tokens!D:D)+SynthOutputTokens)*J5/1000000)*MonthlyCaseVolume*(1+InfrastructurePct) -> 8987.364 | M5: Claude Sonnet 4.6 | N5: 64709.021 | AB5: Selected Model | AC5: =$C$4 -> 1296.1382 | AE5: 6000 | AF5: =$H$87 -> 2472.126 | AG5: =$H$92 -> 6192.51 | AH5: =($I$6*$C$7/1000000+$J$6*$D$7/1000000)*AE5*(1+$A$24) -> 56.706048 | AI5: =($I$8*$C$7/1000000+$J$8*$D$7/1000000)*AE5*(1+$A$24) -> 1296.1382 | AJ5: =($I$10*$C$7/1000000+$J$10*$D$7/1000000)*AE5*(1+$A$24) -> 783.55642
A6: TOKEN PRICING | C6: INPUT TOKENS/CASE | D6: OUTPUT TOKENS/CASE | E6: INPUT:OUTPUT RATIO | F6: DAILY COST | H6: Nova Micro | I6: ='AWS LLM Pricing'!D5 -> 0.035 | J6: ='AWS LLM Pricing'!E5 -> 0.14 | K6: =((SUM(Per_Agent_Tokens!C:C)+SynthInputTokens)*I6/1000000+(SUM(Per_Agent_Tokens!D:D)+SynthOutputTokens)*J6/1000000)*MonthlyCaseVolume*(1+InfrastructurePct) -> 56.706048 | M6: Nova Premier | N6: 53924.184 | AB6: Llama 3.3 70B | AC6: =K10 -> 783.55642 | AE6: 12000 | AF6: =$H$87 -> 2472.126 | AG6: =$H$92 -> 6192.51 | AH6: =($I$6*$C$7/1000000+$J$6*$D$7/1000000)*AE6*(1+$A$24) -> 113.4121 | AI6: =($I$8*$C$7/1000000+$J$8*$D$7/1000000)*AE6*(1+$A$24) -> 2592.2765 | AJ6: =($I$10*$C$7/1000000+$J$10*$D$7/1000000)*AE6*(1+$A$24) -> 1567.1128
A7: Input (per 1M tokens) | C7: =SUM(Per_Agent_Tokens!C:C)+SynthInputTokens -> 126524 | D7: =SUM(Per_Agent_Tokens!D:D)+SynthOutputTokens -> 24625 | E7: =ROUND(C7/D7,1)&" : 1" -> 5.1 : 1 | F7: =C4/30 -> 43.204608 | H7: Nova Lite | I7: ='AWS LLM Pricing'!D6 -> 0.06 | J7: ='AWS LLM Pricing'!E6 -> 0.24 | K7: =((SUM(Per_Agent_Tokens!C:C)+SynthInputTokens)*I7/1000000+(SUM(Per_Agent_Tokens!D:D)+SynthOutputTokens)*J7/1000000)*MonthlyCaseVolume*(1+InfrastructurePct) -> 97.210368 | M7: Claude Haiku 4.5 | N7: 21569.674 | AB7: Nova Pro | AC7: =K8 -> 1296.1382 | AE7: 25000 | AF7: =$H$87 -> 2472.126 | AG7: =$H$92 -> 6192.51 | AH7: =($I$6*$C$7/1000000+$J$6*$D$7/1000000)*AE7*(1+$A$24) -> 236.2752 | AI7: =($I$8*$C$7/1000000+$J$8*$D$7/1000000)*AE7*(1+$A$24) -> 5400.576 | AJ7: =($I$10*$C$7/1000000+$J$10*$D$7/1000000)*AE7*(1+$A$24) -> 3264.8184
A8: =VLOOKUP(A4,'AWS LLM Pricing'!B:E,3,FALSE) -> 0.8 | H8: Nova Pro | I8: ='AWS LLM Pricing'!D7 -> 0.8 | J8: ='AWS LLM Pricing'!E7 -> 3.2 | K8: =((SUM(Per_Agent_Tokens!C:C)+SynthInputTokens)*I8/1000000+(SUM(Per_Agent_Tokens!D:D)+SynthOutputTokens)*J8/1000000)*MonthlyCaseVolume*(1+InfrastructurePct) -> 1296.1382 | M8: Nova Pro | N8: 15553.659 | AB8: Nova Micro | AC8: =K6 -> 56.706048 | AE8: 50000 | AF8: =$H$87 -> 2472.126 | AG8: =$H$92 -> 6192.51 | AH8: =($I$6*$C$7/1000000+$J$6*$D$7/1000000)*AE8*(1+$A$24) -> 472.5504 | AI8: =($I$8*$C$7/1000000+$J$8*$D$7/1000000)*AE8*(1+$A$24) -> 10801.152 | AJ8: =($I$10*$C$7/1000000+$J$10*$D$7/1000000)*AE8*(1+$A$24) -> 6529.6368
A9: Output (per 1M tokens) | C9: COST BREAKDOWN | H9: Nova Premier | I9: ='AWS LLM Pricing'!D8 -> 2.5 | J9: ='AWS LLM Pricing'!E8 -> 12.5 | K9: =((SUM(Per_Agent_Tokens!C:C)+SynthInputTokens)*I9/1000000+(SUM(Per_Agent_Tokens!D:D)+SynthOutputTokens)*J9/1000000)*MonthlyCaseVolume*(1+InfrastructurePct) -> 4493.682 | M9: Llama 3.3 70B | N9: 9402.677 | AE9: 100000 | AF9: =$H$87 -> 2472.126 | AG9: =$H$92 -> 6192.51 | AH9: =($I$6*$C$7/1000000+$J$6*$D$7/1000000)*AE9*(1+$A$24) -> 945.1008 | AI9: =($I$8*$C$7/1000000+$J$8*$D$7/1000000)*AE9*(1+$A$24) -> 21602.304 | AJ9: =($I$10*$C$7/1000000+$J$10*$D$7/1000000)*AE9*(1+$A$24) -> 13059.274
A10: =VLOOKUP(A4,'AWS LLM Pricing'!B:E,4,FALSE) -> 3.2 | C10: Component | D10: Monthly Cost | E10: % of Total | H10: Llama 3.3 70B | I10: ='AWS LLM Pricing'!D9 -> 0.72 | J10: ='AWS LLM Pricing'!E9 -> 0.72 | K10: =((SUM(Per_Agent_Tokens!C:C)+SynthInputTokens)*I10/1000000+(SUM(Per_Agent_Tokens!D:D)+SynthOutputTokens)*J10/1000000)*MonthlyCaseVolume*(1+InfrastructurePct) -> 783.55642 | M10: Nova Lite | N10: 1166.5244
C11: Input Tokens | D11: =(SUM(Per_Agent_Tokens!C:C)+SynthInputTokens)*InputPrice/1000000*MonthlyCaseVolume -> 607.3152 | E11: =D11/(C4/(1+InfrastructurePct)) -> 0.56226891 | M11: Nova Micro | N11: 680.47258
A12: VOLUME SETTINGS | C12: Output Tokens | D12: =(SUM(Per_Agent_Tokens!D:D)+SynthOutputTokens)*OutputPrice/1000000*MonthlyCaseVolume -> 472.8 | E12: =D12/(C4/(1+InfrastructurePct)) -> 0.43773109 | H12: CATEGORY TOKEN USAGE
A13: Monthly Case Volume | C13: Infrastructure | D13: =(D11+D12)*InfrastructurePct -> 216.02304 | E13: =D13/C4 -> 0.16666667 | H13: Category | I13: Agents | J13: Total Tokens | K13: % of Total
A14: 6000 | C14: TOTAL | D14: =SUM(D11:D13) -> 1296.1382 | E14: =SUM(E11:E13) -> 1.1666667 | H14: Income | I14: =Category_Breakdown!B2 -> 7 | J14: =Category_Breakdown!E2 -> 23444 | K14: =J14/SUM(Category_Breakdown!E2:E10) -> 0.17093818
A15: Number of Agents | H15: Non-Financial | I15: =Category_Breakdown!B3 -> 5 | J15: =Category_Breakdown!E3 -> 22087 | K15: =J15/SUM(Category_Breakdown!E2:E10) -> 0.16104383
A16: 38 | C16: OPTIMIZATION SCENARIOS | H16: Residency/Citizenship | I16: =Category_Breakdown!B4 -> 5 | J16: =Category_Breakdown!E4 -> 19919 | K16: =J16/SUM(Category_Breakdown!E2:E10) -> 0.1452362
C17: Scenario | D17: Est. Tokens | E17: Reduction | F17: Monthly Savings | H17: Verification/Docs | I17: =Category_Breakdown!B5 -> 5 | J17: =Category_Breakdown!E5 -> 18567 | K17: =J17/SUM(Category_Breakdown!E2:E10) -> 0.13537831
A18: OVERHEAD CONFIG | C18: Full Naive Run | D18: =Z_Optimization_Scenarios!C2 -> 137149 | E18: =Z_Optimization_Scenarios!D2/100 -> 0 | F18: 0 | H18: Identity/Household | I18: =Category_Breakdown!B6 -> 4 | J18: =Category_Breakdown!E6 -> 16233 | K18: =J18/SUM(Category_Breakdown!E2:E10) -> 0.11836032
A19: Synthesis Input Tokens | C19: Core Only Run | D19: =Z_Optimization_Scenarios!C3 -> 112114 | E19: =Z_Optimization_Scenarios!D3/100 -> 0.183 | F19: =C4*(1-D19/Z_Optimization_Scenarios!C2) -> 236.59539 | H19: Resources | I19: =Category_Breakdown!B7 -> 5 | J19: =Category_Breakdown!E7 -> 15564 | K19: =J19/SUM(Category_Breakdown!E2:E10) -> 0.11348242
A20: 10000 | C20: Context Sharing | D20: =Z_Optimization_Scenarios!C4 -> 95000 | E20: =Z_Optimization_Scenarios!D4/100 -> 0.307 | F20: =C4*(1-D20/Z_Optimization_Scenarios!C2) -> 398.33269 | H20: Categorical Det. | I20: =Category_Breakdown!B8 -> 3 | J20: =Category_Breakdown!E8 -> 9215 | K20: =J20/SUM(Category_Breakdown!E2:E10) -> 0.067189699
A21: Synthesis Output Tokens | C21: Hierarchical Design | D21: =Z_Optimization_Scenarios!C5 -> 85000 | E21: =Z_Optimization_Scenarios!D5/100 -> 0.38 | F21: =C4*(1-D21/Z_Optimization_Scenarios!C2) -> 492.83854 | H21: Deductions | I21: =Category_Breakdown!B9 -> 2 | J21: =Category_Breakdown!E9 -> 6434 | K21: =J21/SUM(Category_Breakdown!E2:E10) -> 0.046912482
A22: 4000 | C22: Hybrid Rules+LLM | D22: =Z_Optimization_Scenarios!C6 -> 65000 | E22: =Z_Optimization_Scenarios!D6/100 -> 0.526 | F22: =C4*(1-D22/Z_Optimization_Scenarios!C2) -> 681.85023 | H22: Timeliness | I22: =Category_Breakdown!B10 -> 2 | J22: =Category_Breakdown!E10 -> 5686 | K22: =J22/SUM(Category_Breakdown!E2:E10) -> 0.04145856
A23: Infrastructure Cost %
A24: 0.2
C41: MULTI-MODEL COST ANALYSIS
C42: ANNUAL COST PROJECTION BY MODEL
C43: Model | D43: Jan | E43: Feb | F43: Mar | G43: Apr | H43: May | I43: Jun | J43: Jul | K43: Aug | L43: Sep | M43: Oct | N43: Nov | O43: Dec
C44: =H3 -> Claude Haiku 4.5 | D44: =K3*1 -> 1797.4728 | E44: =K3*2 -> 3594.9456 | F44: =K3*3 -> 5392.4184 | G44: =K3*4 -> 7189.8912 | H44: =K3*5 -> 8987.364 | I44: =K3*6 -> 10784.837 | J44: =K3*7 -> 12582.31 | K44: =K3*8 -> 14379.782 | L44: =K3*9 -> 16177.255 | M44: =K3*10 -> 17974.728 | N44: =K3*11 -> 19772.201 | O44: =K3*12 -> 21569.674
C45: =H4 -> Claude Sonnet 4.6 | D45: =K4*1 -> 5392.4184 | E45: =K4*2 -> 10784.837 | F45: =K4*3 -> 16177.255 | G45: =K4*4 -> 21569.674 | H45: =K4*5 -> 26962.092 | I45: =K4*6 -> 32354.51 | J45: =K4*7 -> 37746.929 | K45: =K4*8 -> 43139.347 | L45: =K4*9 -> 48531.766 | M45: =K4*10 -> 53924.184 | N45: =K4*11 -> 59316.602 | O45: =K4*12 -> 64709.021
C46: =H5 -> Claude Opus 4.7 | D46: =K5*1 -> 8987.364 | E46: =K5*2 -> 17974.728 | F46: =K5*3 -> 26962.092 | G46: =K5*4 -> 35949.456 | H46: =K5*5 -> 44936.82 | I46: =K5*6 -> 53924.184 | J46: =K5*7 -> 62911.548 | K46: =K5*8 -> 71898.912 | L46: =K5*9 -> 80886.276 | M46: =K5*10 -> 89873.64 | N46: =K5*11 -> 98861.004 | O46: =K5*12 -> 107848.37
C47: =H6 -> Nova Micro | D47: =K6*1 -> 56.706048 | E47: =K6*2 -> 113.4121 | F47: =K6*3 -> 170.11814 | G47: =K6*4 -> 226.82419 | H47: =K6*5 -> 283.53024 | I47: =K6*6 -> 340.23629 | J47: =K6*7 -> 396.94234 | K47: =K6*8 -> 453.64838 | L47: =K6*9 -> 510.35443 | M47: =K6*10 -> 567.06048 | N47: =K6*11 -> 623.76653 | O47: =K6*12 -> 680.47258
C48: =H7 -> Nova Lite | D48: =K7*1 -> 97.210368 | E48: =K7*2 -> 194.42074 | F48: =K7*3 -> 291.6311 | G48: =K7*4 -> 388.84147 | H48: =K7*5 -> 486.05184 | I48: =K7*6 -> 583.26221 | J48: =K7*7 -> 680.47258 | K48: =K7*8 -> 777.68294 | L48: =K7*9 -> 874.89331 | M48: =K7*10 -> 972.10368 | N48: =K7*11 -> 1069.314 | O48: =K7*12 -> 1166.5244
C49: =H8 -> Nova Pro | D49: =K8*1 -> 1296.1382 | E49: =K8*2 -> 2592.2765 | F49: =K8*3 -> 3888.4147 | G49: =K8*4 -> 5184.553 | H49: =K8*5 -> 6480.6912 | I49: =K8*6 -> 7776.8294 | J49: =K8*7 -> 9072.9677 | K49: =K8*8 -> 10369.106 | L49: =K8*9 -> 11665.244 | M49: =K8*10 -> 12961.382 | N49: =K8*11 -> 14257.521 | O49: =K8*12 -> 15553.659
C50: =H9 -> Nova Premier | D50: =K9*1 -> 4493.682 | E50: =K9*2 -> 8987.364 | F50: =K9*3 -> 13481.046 | G50: =K9*4 -> 17974.728 | H50: =K9*5 -> 22468.41 | I50: =K9*6 -> 26962.092 | J50: =K9*7 -> 31455.774 | K50: =K9*8 -> 35949.456 | L50: =K9*9 -> 40443.138 | M50: =K9*10 -> 44936.82 | N50: =K9*11 -> 49430.502 | O50: =K9*12 -> 53924.184
C51: =H10 -> Llama 3.3 70B | D51: =K10*1 -> 783.55642 | E51: =K10*2 -> 1567.1128 | F51: =K10*3 -> 2350.6692 | G51: =K10*4 -> 3134.2257 | H51: =K10*5 -> 3917.7821 | I51: =K10*6 -> 4701.3385 | J51: =K10*7 -> 5484.8949 | K51: =K10*8 -> 6268.4513 | L51: =K10*9 -> 7052.0077 | M51: =K10*10 -> 7835.5642 | N51: =K10*11 -> 8619.1206 | O51: =K10*12 -> 9402.677
C84: HOSTED MODELS DETAILED ANALYSIS
C85: Self-Hosted Infrastructure Cost Breakdown
C86: Model | D86: Cost/Min | E86: Storage/Unit | F86: Hourly Cost | G86: Daily Cost (24h) | H86: Monthly Cost | I86: Annual Cost | J86: Break-Even Cases | K86: Cost/Case (6K) | L86: vs On-Demand
C87: Llama | D87: 0.05718 | E87: 1.95 | F87: =D87*60 -> 3.4308 | G87: =F87*24 -> 82.3392 | H87: =G87*30+E87 -> 2472.126 | I87: =H87*12 -> 29665.512 | J87: =H87/$D$4 -> 11443.807 | K87: =H87/$A$14 -> 0.412021 | L87: =K87/$D$4 -> 1.9073012
C88: Mistral | D88: 0.05718 | E88: 1.95 | F88: =D88*60 -> 3.4308 | G88: =F88*24 -> 82.3392 | H88: =G88*30+E88 -> 2472.126 | I88: =H88*12 -> 29665.512 | J88: =H88/$D$4 -> 11443.807 | K88: =H88/$A$14 -> 0.412021 | L88: =K88/$D$4 -> 1.9073012
...

Sheet Category_Breakdown
A1: Agent_Category | B1: Num_Agents | C1: Input_Tokens | D1: Output_Tokens | E1: Total_Tokens
A2: Income | B2: 7 | C2: =SUMIF(Per_Agent_Tokens!B:B,"Income",Per_Agent_Tokens!C:C) -> 20294 | D2: =SUMIF(Per_Agent_Tokens!B:B,"Non-Financial",Per_Agent_Tokens!D:D) -> 3150 | E2: =C2+D2 -> 23444
A3: Non-Financial | B3: 5 | C3: =SUMIF(Per_Agent_Tokens!B:B,"Non-Financial",Per_Agent_Tokens!C:C) -> 18412 | D3: =SUMIF(Per_Agent_Tokens!B:B,"Income",Per_Agent_Tokens!D:D) -> 3675 | E3: =C3+D3 -> 22087
A4: Residency_Citizenship | B4: 5 | C4: =SUMIF(Per_Agent_Tokens!B:B,"Residency & Citizenship",Per_Agent_Tokens!C:C) -> 16994 | D4: =SUMIF(Per_Agent_Tokens!B:B,"Residency & Citizenship",Per_Agent_Tokens!D:D) -> 2925 | E4: =C4+D4 -> 19919
A5: Verification_Documentation | B5: 5 | C5: =SUMIF(Per_Agent_Tokens!B:B,"Verification & Documentation",Per_Agent_Tokens!C:C) -> 15642 | D5: =SUMIF(Per_Agent_Tokens!B:B,"Verification & Documentation",Per_Agent_Tokens!D:D) -> 2925 | E5: =C5+D5 -> 18567
A6: Identity_Household | B6: 4 | C6: =SUMIF(Per_Agent_Tokens!B:B,"Identity & Household",Per_Agent_Tokens!C:C) -> 13908 | D6: =SUMIF(Per_Agent_Tokens!B:B,"Identity & Household",Per_Agent_Tokens!D:D) -> 2325 | E6: =C6+D6 -> 16233
A7: Resources | B7: 5 | C7: =SUMIF(Per_Agent_Tokens!B:B,"Resources",Per_Agent_Tokens!C:C) -> 13164 | D7: =SUMIF(Per_Agent_Tokens!B:B,"Resources",Per_Agent_Tokens!D:D) -> 2400 | E7: =C7+D7 -> 15564
A8: Categorical_Determination | B8: 3 | C8: =SUMIF(Per_Agent_Tokens!B:B,"Categorical Determination",Per_Agent_Tokens!C:C) -> 7790 | D8: =SUMIF(Per_Agent_Tokens!B:B,"Categorical Determination",Per_Agent_Tokens!D:D) -> 1425 | E8: =C8+D8 -> 9215
A9: Deductions | B9: 2 | C9: =SUMIF(Per_Agent_Tokens!B:B,"Deductions",Per_Agent_Tokens!C:C) -> 5534 | D9: =SUMIF(Per_Agent_Tokens!B:B,"Deductions",Per_Agent_Tokens!D:D) -> 900 | E9: =C9+D9 -> 6434
A10: Timeliness | B10: 2 | C10: =SUMIF(Per_Agent_Tokens!B:B,"Timeliness",Per_Agent_Tokens!C:C) -> 4786 | D10: =SUMIF(Per_Agent_Tokens!B:B,"Timeliness",Per_Agent_Tokens!D:D) -> 900 | E10: =C10+D10 -> 5686
B12: =SUM(B2:B10) -> 38

Sheet Per_Agent_Tokens
A1: Question_Code | B1: Agent_Category | C1: Input_Tokens | D1: Output_Tokens | E1: Total_Tokens
A2: IH_1 | B2: Identity & Household | C2: 4168 | D2: 675 | E2: =SUM(C2:D2) -> 4843
A3: IH_2 | B3: Identity & Household | C3: 2740 | D3: 450 | E3: =SUM(C3:D3) -> 3190
A4: IH_3 | B4: Identity & Household | C4: 3440 | D4: 600 | E4: =SUM(C4:D4) -> 4040
A5: IH_4 | B5: Identity & Household | C5: 3560 | D5: 600 | E5: =SUM(C5:D5) -> 4160
A6: RC_1 | B6: Residency & Citizenship | C6: 4266 | D6: 675 | E6: =SUM(C6:D6) -> 4941
A7: RC_2 | B7: Residency & Citizenship | C7: 4008 | D7: 675 | E7: =SUM(C7:D7) -> 4683
A8: RC_3 | B8: Residency & Citizenship | C8: 2950 | D8: 525 | E8: =SUM(C8:D8) -> 3475
A9: RC_4 | B9: Residency & Citizenship | C9: 2644 | D9: 525 | E9: =SUM(C9:D9) -> 3169
A10: RC_5 | B10: Residency & Citizenship | C10: 3126 | D10: 525 | E10: =SUM(C10:D10) -> 3651
A11: TL_1 | B11: Timeliness | C11: 2404 | D11: 450 | E11: =SUM(C11:D11) -> 2854
A12: TL_2 | B12: Timeliness | C12: 2382 | D12: 450 | E12: =SUM(C12:D12) -> 2832
A13: NF_1 | B13: Non-Financial | C13: 3238 | D13: 600 | E13: =SUM(C13:D13) -> 3838
... A39: VD_5 | B39: Verification & Documentation | C39: 2798 | D39: 600 | E39: =SUM(C39:D39) -> 3398

Sheet AWS LLM Pricing
A1: Provider | B1: Model Name | C1: AWS Service | D1: Input Token Cost (USD / 1M tokens) | E1: Output Token Cost (USD / 1M tokens) | F1: Hosting / Compute Cost | G1: Hosting Notes | H1: Context Window | I1: Notes
A2: Anthropic | B2: Claude Haiku 4.5 | C2: Amazon Bedrock | D2: 1 | E2: 5 | F2: On-demand included; Provisioned Throughput available | G2: Provisioned throughput pricing varies by region/commitment | H2: 200K–1M | I2: Low-cost fast inference
A3: Anthropic | B3: Claude Sonnet 4.6 | C3: Amazon Bedrock | D3: 3 | E3: 15 | F3: On-demand included; Provisioned Throughput available | G3: Most common enterprise model | H3: 1M | I3: Strong coding/reasoning balance
A4: Anthropic | B4: Claude Opus 4.7 | C4: Amazon Bedrock | D4: 5 | E4: 25 | F4: On-demand included; Provisioned Throughput available | G4: Higher-end reasoning model | H4: 1M | I4: Frontier reasoning model
A5: Amazon | B5: Nova Micro | C5: Amazon Bedrock | D5: 0.035 | E5: 0.14 | F5: On-demand included | G5: No dedicated hosting required for serverless inference | H5: 128K | I5: Lowest-cost AWS-native model
A6: Amazon | B6: Nova Lite | C6: Amazon Bedrock | D6: 0.06 | E6: 0.24 | F6: On-demand included | G6: Optimized for lightweight tasks | H6: 300K | I6: Balanced low-cost model
A7: Amazon | B7: Nova Pro | C7: Amazon Bedrock | D7: 0.8 | E7: 3.2 | F7: On-demand included | G7: General enterprise workloads | H7: 300K | I7: Good price/performance
A8: Amazon | B8: Nova Premier | C8: Amazon Bedrock | D8: 2.5 | E8: 12.5 | F8: On-demand included | G8: Premium AWS-native reasoning model | H8: 1M | I8: Enterprise/high-quality generation
A9: Meta | B9: Llama 3.3 70B | C9: Amazon Bedrock | D9: 0.72 | E9: 0.72 | F9: On-demand included; Provisioned Throughput available | G9: Open-weight Meta model | H9: 128K | I9: Strong open model
A10: Meta | B10: Llama 3.1 405B | C10: Amazon Bedrock | D10: 5.32 | E10: 16 | F10: On-demand included; Provisioned Throughput available | G10: Very large open-weight model | H10: 128K | I10: High-end open model
A11: Mistral | B11: Mistral Large | C11: Amazon Bedrock | D11: 4 | E11: 12 | F11: On-demand included | G11: European-hosted model provider | H11: 128K | I11: Enterprise multilingual
A12: Cohere | B12: Command R+ | C12: Amazon Bedrock | D12: 3 | E12: 15 | F12: On-demand included | G12: RAG-focused model | H12: 128K | I12: Optimized for enterprise retrieval
A13: OpenAI | B13: gpt-oss-120B | C13: Amazon Bedrock | D13: 2.5 | E13: 10 | F13: Self-hosting via SageMaker or Bedrock deployment may require GPU instances | G13: Approximate GPU hosting: $2.50-$3.50/hr for A10G/A100 class | H13: 128K | I13: Open-weight OpenAI model
A14: OpenAI | B14: gpt-oss-20B | C14: Amazon Bedrock | D14: 0.75 | E14: 3 | F14: Can run on smaller GPU infrastructure | G14: Approximate GPU hosting: ~$1/hr-$2/hr | H14: 128K | I14: Smaller edge-friendly model
A15: Google | B15: Gemma 3 4B | C15: Amazon Bedrock | D15: 0.04 | E15: 0.08
A16: Google | B16: Gemma 3 12B | C16: Amazon Bedrock | D16: 0.09 | E16: 0.29
A17: Google | B17: Gemma 3 27B | C17: Amazon Bedrock | D17: 0.023 | E17: 0.38
A21: Hosted Models | B21: Cost Per min | C21: Storage Cost per model unit
A22: Llama | B22: 0.05718 | C22: 1.95
A23: Mistral | B23: 0.05718 | C23: 1.95
A24: Mixtral | B24: 0.05718 | C24: 1.95
A25: Flan | B25: 0.05718 | C25: 1.95
A26: Qwen | B26: 0.05718 | C26: 1.95
A27: Open AI | B27: 0.1433 | C27: 1.95

Sheet Z_Core_vs_Rollup
A1: Group | B1: Num_Agents | C1: Input_Tokens | D1: Output_Tokens | E1: Total_Tokens | G1: Rollup_Codes
A2: Core_QA_Agents | B2: =COUNTA(Per_Agent_Tokens!$A:$A)-1-COUNTA($G$2:$G$9) -> 30 | C2: =SUM(Per_Agent_Tokens!$C:$C)-(C3) -> 114394 | D2: =SUM(Per_Agent_Tokens!$D:$D)-(D3) -> 20175 | E2: =(C2)+(D2) -> 134569 | G2: RC_5
A3: Rollup_Step_Agents | B3: =COUNTA($G$2:$G$9) -> 8 | C3: =SUM(SUMIF(Per_Agent_Tokens!$A:$A,$G$2:$G$9,Per_Agent_Tokens!$C:$C)) -> 2130 | D3: =SUM(SUMIF(Per_Agent_Tokens!$A:$A,$G$2:$G$9,Per_Agent_Tokens!$D:$D)) -> 450 | E3: =(C3)+(D3) -> 2580 | G3: RE_5
G4: IN_6
G5: IN_7
G6: CD_2
G7: CD_3
G8: DE_2 | H8: =Z_Core_vs_Rollup!B2XLOOKUP($B$2,'AWS LLM Pricing'!$B$2:$B$14,'AWS LLM Pricing'!$D$2:$D$14) -> #NAME?
G9: VD_5

Sheet Z_Optimization_Scenarios
A1: Scenario | B1: Description | C1: Estimated_Total_Tokens | D1: Reduction_vs_Full_Percent
A2: Full_Naive_Run | B2: All_38_agents_executed_independently | C2: 137149 | D2: 0
A3: Core_Only_Run | B3: Drop_rollup_duplicate_agents | C3: 112114 | D3: 18.3
A4: Core_Optimized_Context_Sharing | B4: Reuse_case_context_across_agents | C4: 95000 | D4: 30.7
A5: Hierarchical_Agent_Design | B5: CD_first_then_targeted_agents | C5: 85000 | D5: 38
A6: Hybrid_Rules_plus_LLM | B6: Deterministic_checks_offloaded | C6: 65000 | D6: 52.6
